Workbook

Sheet Sheet4
A1: Model file name | B1: (All)
A2: Requirement Text | B2: (All)
A4: Count of Table 1-Level 3 ID | B4: Column Labels
A5: Row Labels | B5: L3 | C5: L4 | D5: Grand Total
A6: The 'Backup and Recovery' service shall provide an automated backup policy targeting a Recovery Point Objective (RPO) of <= 24 hours for all 'Customer Data' in platform-managed persistent volumes. | C6: 2 | D6: 2
A7: The 'Centralized Secrets Management' service shall encrypt secrets at rest and in transit using FIPS-approved algorithms. | C7: 4 | D7: 4
A8: The 'Configuration Portal' shall provide a user-friendly interface for environment setup, configuration, and deployment of IDE instances. | B8: 2 | D8: 2
A9: The 'Consolidated Admin Interface' shall provide a module for managing platform-level access permissions. | C9: 11 | D9: 11
A10: The 'Consolidated Admin Interface' shall provide a module for managing user accounts. | B10: 1 | C10: 7 | D10: 8
A11: The 'Consolidated Admin Interface' shall provide a module for managing user roles. | C11: 6 | D11: 6
A12: The 'Consolidated Admin Interface' shall provide an administrative GUI for the 'Centralized Secrets Management' service. | C12: 1 | D12: 1
A13: The 'Cyber compliance evidence' package shall include security scan results (SAST, DAST, container scans). | C13: 4 | D13: 4
A14: The 'Cyber compliance evidence' package shall include the baseline System Security Plan (SSP) and control mappings. | C14: 4 | D14: 4
A15: The 'destroy IDE script' shall perform cryptographic erasure of all associated persistent volumes. | C15: 1 | D15: 1
A16: The IDE (via the IDE Factory) shall produce and publish a validated 'upgrade package' in response to a critical CVE within 48 hours of public disclosure. | C16: 3 | D16: 3
A17: The IDE baseline shall be maintained under a formal Continuous Authorization to Operate (cATO) process, enabled by a provider-side DevSecOps pipeline and customer-side Continuous Monitoring (CONMON). | C17: 3 | D17: 3
A18: The IDE 'destroy IDE script' shall generate a 'Data Destruction Certificate' (audit log) of all destruction activities and component erasure status. | B18: 1 | D18: 1
A19: The IDE Factory shall provide a web-based 'Configuration Portal' for customers to configure and procure new IDE Instances and updates. | C19: 5 | D19: 5
A20: The IDE installation process shall provision a new, dedicated K8s cluster and shall not deploy into a pre-existing, non-IDE K8s cluster. | C20: 1 | D20: 1
A21: The IDE Interface Control Document (ICD) shall define the programmatic API for the 'Centralized Secrets Management' service to enable 'Customer-Integrated Applications' to securely access credentials. | C21: 1 | D21: 1
A22: The IDE platform shall be environment-agnostic, supporting deployment in on-premises, private cloud, public cloud, and fully air-gapped networks. | C22: 7 | D22: 7
A23: The IDE 'Secure Platform' and 'IDE Capability Layer' components shall be configured to comply with NIST SP 800-171 controls. | C23: 3 | D23: 3
A24: The IDE 'Secure Platform' and 'IDE Capability Layer' components shall be configured to comply with NIST SP 800-53 (Rev 5). | C24: 4 | D24: 4
A25: The IDE 'Secure Platform' and 'IDE Capability Layer' components shall be hardened to comply with NIST SP 800-171 controls. | C25: 1 | D25: 1
A26: The IDE 'Secure Platform' and 'IDE Capability Layer' components shall be hardened to comply with NIST SP 800-53 (Rev 5). | C26: 33 | D26: 33
A27: The IDE 'Secure Platform' and its 'Mandated Shared Services' shall provide >= 99.99% availability. | B27: 1 | C27: 2 | D27: 3
A28: The IDE Secure Platform shall enable 'Customer-Integrated Applications' to leverage Mandated Shared Services via adherence to the published IDE Interface Control Document (ICD). | C28: 6 | D28: 6
A29: The IDE Secure Platform shall provide a capability for customers to deploy their own containerized applications ('Customer-Integrated Applications') alongside the IDE Capability Layer. | B29: 1 | D29: 1
A30: The IDE Secure Platform shall provide a mandated shared service for structured data storage (e.g., SQL-compatible). | B30: 1 | C30: 2 | D30: 3
A31: The IDE Secure Platform shall provide a mandated shared service for unstructured data storage (e.g., object storage). | B31: 1 | D31: 1
A32: The IDE shall assign each AI agent a distinct, non-human identity (service account) with a unique, role-based access control (RBAC) profile. | C32: 2 | D32: 2
A33: The IDE shall be delivered as a complete, 'opinionated stack'; deployment of the 'IDE Capability Layer' on a non-IDE platform shall not be supported. | C33: 3 | D33: 3
A34: The IDE shall complete the 'Day 0 Provisioning' scenario (Scenario 5.1.1), from execution of the bootstrap command to operational readiness, in less than four (4) hours. | C34: 2 | D34: 2
A35: The IDE shall complete the 'Platform Patching and Upgrades' scenario (Scenario 5.2.2), from execution of the upgrade command to operational readiness, in under one (1) hour. | C35: 5 | D35: 5
A36: The IDE shall enable dashboard user interaction (e.g., drill-down, filtering) to perform detailed analysis. | B36: 1 | D36: 1
A37: The IDE shall implement data backup procedures to ensure that authoritative data is securely backed up prior to executing the migration or upgrade. | B37: 1 | D37: 1
A38: The IDE shall include a formal, version-controlled Interface Control Document (ICD) as a core product deliverable that defines the technical and security 'contract' for integrating customer applications. | C38: 4 | D38: 4
A39: The IDE shall include documented guidance for the 'destroy IDE script' as part of the core product deliverable. | B39: 1 | D39: 1
A40: The IDE shall integrate all 'Centralized Secrets Management' access and management actions with the 'Centralized Logging' service to ensure all actions are auditable. | C40: 2 | D40: 2
A41: The IDE shall integrate the Software Factory capabilities with the Mandated Shared Service for Centralized Authorization (RBAC). | C41: 1 | D41: 1
...

Sheet IDE_ConOps_4_3_Model_Trace_LVL3
A1: Table 1-Level 3 ID | B1: Baseline L3 Req Text | C1: Model file name | D1: Modeled reference ID | E1: Modeled ConOps Reference | F1: Level 3/4 | G1: Requirement Text | H1: Capability
A2: 2.1.2-F5 | B2: =VLOOKUP(A2,IDE_ConOps_4_3_Model_LVL3!C:H,6,FALSE) -> The IDE shall provide a 'Consolidated Admin Interface' as a secure, web-based UI to provide a single pane of glass for L1/L2 administrative tasks. | C2: IDE_v2_L3_JS.csv | D2: IDE_1 | E2: Sec 3.3.3 | F2: L4 | G2: The Integrated Digital Engineering Ecosystem shall only allow authorized personnel to perform configuration and deployment. | H2: Configure and deploy Integrated Digital Environment
A3: 2.1.2-F11 | B3: =VLOOKUP(A3,IDE_ConOps_4_3_Model_LVL3!C:H,6,FALSE) -> The IDE shall provide a 'Centralized Logging and Monitoring' service as a consolidated pipeline for all security audit events. | C3: IDE_v2_L3_JS.csv | D3: IDE_2 | E3: Sec 2.1.2, 3.3.3 | F3: L4 | G3: The Integrated Digital Engineering Ecosystem shall log and notify authorized users of errors during account management. | H3: User Management
A4: 2.1.2-F19 | B4: =VLOOKUP(A4,IDE_ConOps_4_3_Model_LVL3!C:H,6,FALSE) -> The 'Consolidated Admin Interface' shall provide a module for managing platform-level access permissions. | C4: IDE_v2_L3_JS.csv | D4: IDE_3 | E4: Sec 3.3.3 | F4: L4 | G4: The Integrated Digital Engineering Ecosystem shall enable authorized users to manage user account permissions. | H4: User Management
A5: U.U.3-F2 | B5: =VLOOKUP(A5,IDE_ConOps_4_3_Model_LVL3!C:H,6,FALSE) -> The IDE shall provide an 'IDE Migration Utility' with a guided interface to connect to a backup source. | C5: IDE_v2_L3_JS.csv | D5: IDE_4 | E5: Sec 5.1.2 | F5: L3 | G5: The Integrated Digital Engineering Ecosystem shall establish a migration capability that provides the ability to migrate or upgrade systems and applications. | H5: Application Migration and Upgrade
A6: U.U.3-M1 | B6: =VLOOKUP(A6,IDE_ConOps_4_3_Model_LVL3!C:H,6,FALSE) -> The IDE shall implement data backup procedures to ensure that authoritative data is securely backed up prior to executing the migration or upgrade. | C6: IDE_v2_L3_JS.csv | D6: IDE_5 | E6: Sec 5.1.2 | F6: L3 | G6: The Integrated Digital Engineering Ecosystem shall implement data backup procedures to ensure that authoritative data is securely backed up prior to executing the migration or upgrade. | H6: Application Migration and Upgrade
A7: U.U.3-F4 | B7: =VLOOKUP(A7,IDE_ConOps_4_3_Model_LVL3!C:H,6,FALSE) -> The IDE shall maintain auditable logs, ingested by the 'Centralized Logging' service, of all migration and upgrade activities. | C7: IDE_v2_L3_JS.csv | D7: IDE_6 | E7: Sec 5.1.2 | F7: L4 | G7: The Integrated Digital Engineering Ecosystem shall maintain auditable logs of all migration or upgrade activities, documenting changes made, reasons for changes, and responsible personnel. | H7: Application Migration and Upgrade
A8: U.U.3-F3 | B8: =VLOOKUP(A8,IDE_ConOps_4_3_Model_LVL3!C:H,6,FALSE) -> The IDE shall provide post-migration validation tools to ensure all systems and applications are functioning as expected and no data loss has occurred. | C8: IDE_v2_L3_JS.csv | D8: IDE_7 | E8: Sec 5.1.2 | F8: L3 | G8: The Integrated Digital Engineering Ecosystem shall perform post-migration validation to ensure that all systems and applications are functioning as expected and that no data loss has occurred. | H8: Application Migration and Upgrade
A9: U.U.3-F1 | B9: =VLOOKUP(A9,IDE_ConOps_4_3_Model_LVL3!C:H,6,FALSE) -> The IDE shall provide a 'pre-validation' tool to inspect source (legacy) environments to evaluate migration effects on systems, applications, and data integrity. | C9: IDE_v2_L3_JS.csv | D9: IDE_8 | E9: Sec 5.1.2 | F9: L3 | G9: The Integrated Digital Engineering Ecosystem shall provide pre-validation to evaluate how the migration or upgrade will affect existing systems, applications, and data integrity. | H9: Application Migration and Upgrade
A10: 1.1.1-F4 | B10: =VLOOKUP(A10,IDE_ConOps_4_3_Model_LVL3!C:H,6,FALSE) -> The IDE shall provide a capability for work and backlog management. | C10: IDE_v2_L3_JS.csv | D10: IDE_9 | E10: Sec 2.2 | F10: L4 | G10: The Integrated Digital Engineering Ecosystem shall identify and document stakeholders involved in the migration or upgrade process. | H10: Application Migration and Upgrade
A11: 2.1.2-F5 | B11: =VLOOKUP(A11,IDE_ConOps_4_3_Model_LVL3!C:H,6,FALSE) -> The IDE shall provide a 'Consolidated Admin Interface' as a secure, web-based UI to provide a single pane of glass for L1/L2 administrative tasks. | C11: IDE_v2_L3_JS.csv | D11: IDE_10 | E11: Sec 3.3.3 | F11: L4 | G11: The Integrated Digital Engineering Ecosystem's authorized only personnel shall manage configurations. | H11: Configuration Management
A12: 3.1.1-N5 | B12: =VLOOKUP(A12,IDE_ConOps_4_3_Model_LVL3!C:H,6,FALSE) -> The IDE 'Secure Platform' and 'IDE Capability Layer' components shall be hardened to comply with NIST SP 800-53 (Rev 5). | C12: IDE_v2_L3_JS.csv | D12: IDE_11 | E12: Sec 2.1, 4.1 | F12: L4 | G12: The Integrated Digital Engineering Ecosystem shall adhere to configuration management best practices and standards. | H12: Configuration Management
A13: 2.1.2-F12 | B13: =VLOOKUP(A13,IDE_ConOps_4_3_Model_LVL3!C:H,6,FALSE) -> The IDE shall provide a 'Centralized Health Dashboard' to display real-time performance status of all platform components. | C13: IDE_v2_L3_JS.csv | D13: IDE_12 | E13: Sec 3.3.3 | F13: L4 | G13: The Integrated Digital Engineering Ecosystem shall notify users of failed configuration updates or conflicts. | H13: Configuration Management
... A155: 2.1.2-F18 | B155: =VLOOKUP(A155,IDE_ConOps_4_3_Model_LVL3!C:H,6,FALSE) -> The 'Consolidated Admin Interface' shall provide a module for managing user roles. | C155: IDE_v2_L3_JS.csv | D155: IDE_154 | E155: Sec 3.3.3 | F155: L4 | G155: The Integrated Digital Engineering Ecosystem shall require users to use non-privileged accounts or roles when accessing non security functions. | H155: None
A156: 2.1.2-F6 | B156: =VLOOKUP(A156,IDE_ConOps_4_3_Model_LVL3!C:H,6,FALSE) -> The 'Consolidated Admin Interface' shall provide a module for managing user accounts. | C156: SPL3.csv | D156: 2 | E156: Sec 3.3.3 | F156: L4 | G156: The Secure Platform shall provide a user interface for managing user accounts and access permissions. | H156: Access Control,Deploy Ingress
A157: 2.1.2-F2 | B157: =VLOOKUP(A157,IDE_ConOps_4_3_Model_LVL3!C:H,6,FALSE) -> The IDE shall provide a 'Centralized Health Dashboard' to display real-time health status, performance metrics, and Key Performance Indicators (KPIs) of all platform components. | C157: SPL3.csv | D157: 3 | E157: Sec 3.3.3 | F157: L4 | G157: The Secure Platform shall monitor the performance and health of applications. | H157: Provide Centralized Logging and Monitoring
A158: 3.1.1-F1 | B158: =VLOOKUP(A158,IDE_ConOps_4_3_Model_LVL3!C:H,6,FALSE) -> The IDE shall provide a Kubernetes (K8s) orchestrator as the foundational platform for all containerized services and applications. | C158: SPL3.csv | D158: 4 | E158: Sec 2.1.1 | F158: L4 | G158: The Secure Platform shall provide a container orchestration environment. | H158: Provide Containerization and Microservices Management
A159: 2.1.2-F10 | B159: =VLOOKUP(A159,IDE_ConOps_4_3_Model_LVL3!C:H,6,FALSE) -> The IDE shall provide a 'Centralized Logging and Monitoring' service as a consolidated pipeline for all performance metrics. | C159: SPL3.csv | D159: 5 | E159: Sec 2.1.2, 3.3.3 | F159: L4 | G159: When tracking performance and health metrics, Secure Platform shall monitor and log health data for applications. | H159: Provide Centralized Logging and Monitoring
A160: 2.1.2-F1 | B160: =VLOOKUP(A160,IDE_ConOps_4_3_Model_LVL3!C:H,6,FALSE) -> The IDE shall provide a 'Centralized Logging and Monitoring' service as a consolidated pipeline for all platform logs. | C160: SPL3.csv | D160: 6 | E160: Sec 2.1.2, 3.3.3 | F160: L4 | G160: When log data is created or edited, the Secure Platform shall securely archive and retrieve historical log data. | H160: Automated Retrieval
A161: 3.1.1-F11 | B161: =VLOOKUP(A161,IDE_ConOps_4_3_Model_LVL3!C:H,6,FALSE) -> The IDE shall provide a mandated shared service for 'Centralized Secrets Management' to support the secure storage of platform and application credentials. | C161: SPL3.csv | D161: 7 | E161: Sec 2.1.2 | F161: L4 | G161: Secure Platform Shall encrypt authentication credentials at rest. | H161: Conduct Compliance and Security Checks
A162: 3.1.1-N10 | B162: =VLOOKUP(A162,IDE_ConOps_4_3_Model_LVL3!C:H,6,FALSE) -> The 'Centralized Secrets Management' service shall encrypt secrets at rest and in transit using FIPS-approved algorithms. | C162: SPL3.csv | D162: 8 | E162: Sec 2.1.2 | F162: L4 | G162: Secure Platform Shall encrypt authentication credentials in transit. | H162: None
A163: 1.1.3-F6 | B163: =VLOOKUP(A163,IDE_ConOps_4_3_Model_LVL3!C:H,6,FALSE) -> The IDE shall provide a DoD DevSecOps compliant capability for Continuous Integration and Continuous Deployment (CI/CD). | C163: SPL3.csv | D163: 9 | E163: Sec 2.2 | F163: L4 | G163: The Secure Platform automate deployment and update applications through the Continuous Integration/Continuous pipeline. | H163: Establish Automated CI/CD Pipeline(s)
A164: 3.1.1-F6 | B164: =VLOOKUP(A164,IDE_ConOps_4_3_Model_LVL3!C:H,6,FALSE) -> The IDE shall provide a mandated shared service for 'Backup and Recovery' that performs automated, policy-based backups of the platform state and customer data. | C164: SPL3.csv | D164: 10 | E164: Sec 2.1.2 | F164: L4 | G164: If a failure event occurs, the Secure Platform shall automate failover mechanisms to switch to backup systems. | H164: Backup and Recovery
A165: 3.1.1-F6 | B165: =VLOOKUP(A165,IDE_ConOps_4_3_Model_LVL3!C:H,6,FALSE) -> The IDE shall provide a mandated shared service for 'Backup and Recovery' that performs automated, policy-based backups of the platform state and customer data. | C165: SPL3.csv | D165: 11 | E165: Sec 2.1.2 | F165: L4 | G165: The Secure Platform shall automate backup processes for all deployed systems and data. | H165: Backup and Recovery Operator Deployment
A166: 3.1.1-F5 | B166: =VLOOKUP(A166,IDE_ConOps_4_3_Model_LVL3!C:H,6,FALSE) -> The IDE shall provide a mandated shared 'Service Mesh' that provides service discovery. | C166: SPL3.csv | D166: 12 | E166: Sec 2.1.2 | F166: L4 | G166: The Secure Platform shall automatically discover micro services within the service mesh. | H166: Implement Service Discovery
A167: 3.1.1-F5 | B167: =VLOOKUP(A167,IDE_ConOps_4_3_Model_LVL3!C:H,6,FALSE) -> The IDE shall provide a mandated shared 'Service Mesh' that provides service discovery. | C167: SPL3.csv | D167: 13 | E167: Sec 2.1.2 | F167: L4 | G167: The Secure Platform shall automatically register micro services within the service mesh. | H167: None
... A393: 3.1.1-F9 | B393: =VLOOKUP(A393,IDE_ConOps_4_3_Model_LVL3!C:H,6,FALSE) -> The IDE Secure Platform shall enable 'Customer-Integrated Applications' to leverage Mandated Shared Services via adherence to the published IDE Interface Control Document (ICD). | C393: SPL3.csv | D393: 241 | E393: Sec 2.2.1 | F393: L4 | G393: The Secure Platform shall integrate with manufacturing floor applications, IoT devices and other industrial systems. | H393: Deployment of Hosted Application on the Manufacturing Floor

Sheet SPL3
A1: # | B1: L3 Requirement Name | C1: L3 Requirement Text | D1: Traced To
A2: 1 | B2: 2.2.1.1 Baselined Requirements
A3: 2 | B3: 100000002172 Account and Access Management User Interface | C3: The Secure Platform shall provide a user interface for managing user accounts and access permissions. | D3: Access Control,Deploy Ingress
A4: 3 | B4: 100000002173 Application Health Monitoring | C4: The Secure Platform shall monitor the performance and health of applications. | D4: Provide Centralized Logging and Monitoring
A5: 4 | B5: 100000002174 Application Hosting in Kubernetes | C5: The Secure Platform shall provide a container orchestration environment. | D5: Provide Containerization and Microservices Management
A6: 5 | B6: 100000002175 Application Performance and Health Metrics | C6: When tracking performance and health metrics, Secure Platform shall monitor and log health data for applications. | D6: Provide Centralized Logging and Monitoring
A7: 6 | B7: 100000002176 Archive and Retrieval of Historical Log Data | C7: When log data is created or edited, the Secure Platform shall securely archive and retrieve historical log data. | D7: Automated Retrieval
A8: 7 | B8: 100000002177 Authentication Credential Encryption at Rest | C8: Secure Platform Shall encrypt authentication credentials at rest. | D8: Conduct Compliance and Security Checks
A9: 8 | B9: 100000002178 Authentication Credential Encryption in Transit | C9: Secure Platform Shall encrypt authentication credentials in transit.
A10: 9 | B10: 100000002179 Automated Application Deployment | C10: The Secure Platform automate deployment and update applications through the Continuous Integration/Continuous pipeline. | D10: Establish Automated CI/CD Pipeline(s)
A11: 10 | B11: 100000002180 Automated Backup Failover | C11: If a failure event occurs, the Secure Platform shall automate failover mechanisms to switch to backup systems. | D11: Backup and Recovery
A12: 11 | B12: 100000002181 Automated Backup of Deployed Systems and Data | C12: The Secure Platform shall automate backup processes for all deployed systems and data. | D12: Backup and Recovery Operator Deployment
A13: 12 | B13: 100000002182 Automated Discovery of Micro services | C13: The Secure Platform shall automatically discover micro services within the service mesh. | D13: Implement Service Discovery
A14: 13 | B14: 100000002183 Automated Registration of Micro services | C14: The Secure Platform shall automatically register micro services within the service mesh.
A15: 14 | B15: 100000002184 Automated Secrets Rotation | C15: Secure Platform shall enforce automated rotation of secrets. | D15: Conduct Compliance and Security Checks,Rotate Secrets
A16: 15 | B16: 100000002185 Availability and Disaster Recovering Testing | C16: The Secure Platform shall implement periodic testing of disaster recovery mechanisms. | D16: Disaster Recovery
A17: 16 | B17: 100000002186 Availability Metric Reporting | C17: The Secure Platform shall log and monitor for availability-related metrics and events. | D17: Provide Centralized Logging and Monitoring
A18: 17 | B18: 100000002187 Backup and Recovery Documentation | C18: The Secure Platform shall provide documentation for managing backup and recovery processes. | D18: Backup and Recovery,Define Backup Policy (Application Config),Define Backup Policy (Cluster Config)
A19: 18 | B19: 100000002188 Backup and Recovery of Containerized Applications | C19: When requested, the Secure Platform shall backup and recover containerized applications and their associated data. | D19: Backup and Recovery,Backup and Recovery Operator Deployment
A20: 19 | B20: 100000002189 Backup and Recovery Validation | C20: The Secure Platform shall test and validate the backup and recovery process. | D20: Backup and Recovery
A21: 20 | B21: 100000002190 Backup Process User Interface | C21: While managing and monitoring backup processes, the Secure Platform shall provide a user interface. | D21: Backup and Recovery
A22: 21 | B22: 100000002191 Centralized Logging of Application Components | C22: The Secure Platform shall have centralized logging for required application components. | D22: Provide Centralized Logging and Monitoring
A23: 22 | B23: 100000002192 Centralized Logging of Infrastructure Components | C23: The Secure Platform shall provide centralized logging for required infrastructure components. | D23: Provide Centralized Logging and Monitoring
A24: 23 | B24: 100000002193 CI/CD Pipeline Logging | C24: The Secure Platform shall create detailed logs of Continuous Integration/Continuous Delivery pipeline execution. | D24: Provide Centralized Logging and Monitoring
A25: 24 | B25: 100000002194 CI/CD Pipeline Status and Performance Visualization | C25: The Secure Platform shall provide dashboard interfaces to visualize the status and performance of Continuous Integration/Continuous Deployment pipelines. | D25: Automated Continuous Integration and Continuous Delivery (CI/CD),Establish Automated CI/CD Pipeline(s)
A26: 25 | B26: 100000002195 CI/CD Pipeline Status Visualization | C26: The Secure Platform shall provide Continuous Integration/Continuous Deployment pipeline status notification. | D26: Establish Automated CI/CD Pipeline(s)
... A29: 28 | B29: 100000002198 Compliance Audit of VM Configuration | C29: The Secure Platform shall employ compliance auditing of VM configurations. | D29: Perform Configuration Management
A30: 29 | B30: 100000002199 Compliance Audit of VM Management Activities | C30: The Secure Platform shall employ compliance auditing of VM management activities.
A31: 30 | B31: 100000002200 Compliance Auditing of Configuration Management | C31: The Secure Platform shall employ compliance auditing of configuration management activities.
A32: 31 | B32: 100000002201 Compliance Auditing of Provisioning | C32: The Secure Platform shall employ compliance auditing of provisioning activities.
A33: 32 | B33: 100000002202 Component Health and Performance Monitoring | C33: The Secure Platform shall monitor the performance and health of infrastructure and application components. | D33: Container Security Scanner Deployed
A34: 33 | B34: 100000002203 Configuration Drift Detection | C34: The Secure Platform shall detect configuration drifts. | D34: Perform Configuration Management,Platform Baselined and Monitored for Drift
A35: 34 | B35: 100000002204 Configuration Drift Detection Alerts | C35: The Secure Platform shall provide configuration drift alerts.
A36: 35 | B36: 100000002205 Configuration Management Script Version Control | C36: The Secure Platform shall employ version control of configuration management scripts. | D36: Store scripts for Version Control
A37: 36 | B37: 100000002206 Configuration Management User Interface Manager | C37: The Secure Platform shall provide a user interface for managing provisioning scripts. | D37: Perform Configuration Management
A38: 37 | B38: 100000002207 Configuration Tool Environment-Specific Tailoring | C38: While the Secure Platform is being deployed, it shall manage environment-specific settings. | D38: Perform Configuration Management
A39: 38 | B39: 100000002208 Containerized Application Deployment via CI/CD Pipeline | C39: The Secure Platform shall deploy containerized applications through a Continuous Integration/ Continuous Deployment pipeline. | D39: Deploy to Approval and Production Environment,Deploy Container-based Application
A40: 39 | B40: 100000002209 Containerized Application Health Monitoring | C40: The Secure Platform shall monitor containerized application health. | D40: Verify System Health and Metrics
A41: 40 | B41: 100000002210 Containerized Application Health Reporting | C41: When health issues are detected in containerized applications, the Secure Platform shall deploy alerts and notifications. | D41: Verify System Health and Metrics
A42: 41 | B42: 100000002211 Containerized Application Security Controls | C42: The Secure Platform shall implement security measures for containerized applications in accordance with NIST SP 800-190. | D42: Conduct Compliance and Security Checks
...

Sheet IDE_v2_L3_JS
A1: IDE_Requirement_Id | B1: IDE Capability | C1: Requirement Text
A2: IDE_1 | B2: Configure and deploy Integrated Digital Environment | C2: The Integrated Digital Engineering Ecosystem shall only allow authorized personnel to perform configuration and deployment.
A3: IDE_2 | B3: User Management | C3: The Integrated Digital Engineering Ecosystem shall log and notify authorized users of errors during account management.
A4: IDE_3 | B4: User Management | C4: The Integrated Digital Engineering Ecosystem shall enable authorized users to manage user account permissions.
A5: IDE_4 | B5: Application Migration and Upgrade | C5: The Integrated Digital Engineering Ecosystem shall establish a migration capability that provides the ability to migrate or upgrade systems and applications.
A6: IDE_5 | B6: Application Migration and Upgrade | C6: The Integrated Digital Engineering Ecosystem shall implement data backup procedures to ensure that authoritative data is securely backed up prior to executing the migration or upgrade.
A7: IDE_6 | B7: Application Migration and Upgrade | C7: The Integrated Digital Engineering Ecosystem shall maintain auditable logs of all migration or upgrade activities, documenting changes made, reasons for changes, and responsible personnel.
A8: IDE_7 | B8: Application Migration and Upgrade | C8: The Integrated Digital Engineering Ecosystem shall perform post-migration validation to ensure that all systems and applications are functioning as expected and that no data loss has occurred.
A9: IDE_8 | B9: Application Migration and Upgrade | C9: The Integrated Digital Engineering Ecosystem shall provide pre-validation to evaluate how the migration or upgrade will affect existing systems, applications, and data integrity.
A10: IDE_9 | B10: Application Migration and Upgrade | C10: The Integrated Digital Engineering Ecosystem shall identify and document stakeholders involved in the migration or upgrade process.
A11: IDE_10 | B11: Configuration Management | C11: The Integrated Digital Engineering Ecosystem's authorized only personnel shall manage configurations.
A12: IDE_11 | B12: Configuration Management | C12: The Integrated Digital Engineering Ecosystem shall adhere to configuration management best practices and standards.
... A87: IDE_86 | B87: User Management | C87: The Integrated Digital Engineering Ecosystem shall allow authorized users to manage user accounts within the digital ecosystem.
A88: IDE_87 | C88: The Integrated Digital Engineering Ecosystem shall limit access for processes acting on behalf of authorized users.
A89: IDE_88 | C89: The integrated Digital Engineering Ecosystem shall perform vulnerability scans in applications containing CUI weekly
A90: IDE_89 | C90: The Integrated Digital Engineering Ecosystem shall review, approve or disapprove changes to IDE systems.
A91: IDE_90 | C91: The Integrated Digital Engineering Ecosystem shall terminate a user session automatically after any of the defined conditions occur.
A92: IDE_91 | C92: The Integrated Digital Engineering Ecosystem shall track and manage configuration changes across integrated tools and environments throughout the systems development life cycle.
A93: IDE_92 | C93: The Integrated Digital Engineering Ecosystem shall capture the execution of privileged functions in audit logs.
A94: IDE_93 | C94: The Integrated Digital Engineering Ecosystem shall check media containing diagnostic and test programs for malicious code before the media is used in systems.
A95: IDE_94 | C95: The Integrated Digital Engineering Ecosystem shall prevent installation of software by users
A96: IDE_95 | C96: The Integrated Digital Engineering Ecosystem customers shall control access to media containing CUI.
A97: IDE_96 | C97: The Integrated Digital Engineering Ecosystem shall correct system flaws within the specified time frame.
A98: IDE_97 | C98: The Integrated Digital Engineering Ecosystem shall define authorizations for controlling the flow of CUI.
A99: IDE_98 | C99: The Integrated Digital Engineering Ecosystem shall document incidents.
... A155: IDE_154 | C155: The Integrated Digital Engineering Ecosystem shall require users to use non-privileged accounts or roles when accessing non security functions.

Sheet IDE_ConOps_4_3_Model_LVL3
A1: Level 1 ID | B1: Level 2 ID | C1: Level 3 ID | D1: Component | E1: L3 Requirement Type | F1: Capability | G1: Level 3 Requirement name | H1: Level 3 Requirement text | I1: Verification Method | J1: IDE Conops Section References | K1: Source | L1: Action taken | M1: Modeled ConOps Reference
A2: 1 | B2: 1.1 | C2: 1.1.1-F1 | D2: Capability | E2: F | F2: Planning & Collaboration | G2: P&C Wiki Capability | H2: The IDE shall provide a capability for enterprise wiki collaboration. | I2: Demonstrate | J2: Sec 2.2 | K2: 4.3 ConOps | L2: Updated
A3: 1 | B3: 1.1 | C3: 1.1.1-F2 | D3: Capability | E3: F | F3: Planning & Collaboration | G3: P&C SSO Integration (AuthN) | H3: The IDE shall integrate the Planning and Collaboration capabilities with the Mandated Shared Service for Centralized Authentication (SSO). | I3: Test | J3: Sec 2.1.2, 2.2 | K3: 4.3 ConOps | L3: Updated
A4: 1 | B4: 1.1 | C4: 1.1.1-F3 | D4: Capability | E4: F | F4: Planning & Collaboration | G4: P&C Logging Integration | H4: The IDE shall integrate the Planning and Collaboration capabilities with the Mandated Shared Service for Centralized Logging. | I4: Test | J4: Sec 2.1.2, 2.2 | K4: 4.3 ConOps | L4: Updated
A5: 1 | B5: 1.1 | C5: 1.1.1-F4 | D5: Capability | E5: F | F5: Planning & Collaboration | G5: P&C Work Management Capability | H5: The IDE shall provide a capability for work and backlog management. | I5: Demonstrate | J5: Sec 2.2 | K5: 4.3 ConOps | L5: Added
A6: 1 | B6: 1.1 | C6: 1.1.1-F5 | D6: Capability | E6: F | F6: Planning & Collaboration | G6: P&C Instant Messaging Capability | H6: The IDE shall provide a capability for instant messaging. | I6: Demonstrate | J6: Sec 2.2 | K6: 4.3 ConOps | L6: Added
A7: 1 | B7: 1.1 | C7: 1.1.1-F6 | D7: Capability | E7: F | F7: Planning & Collaboration | G7: P&C Digital Whiteboard Capability | H7: The IDE shall provide a capability for digital whiteboard collaboration. | I7: Demonstrate | J7: Sec 2.2 | K7: 4.3 ConOps | L7: Added
A8: 1 | B8: 1.1 | C8: 1.1.1-F7 | D8: Capability | E8: F | F8: Planning & Collaboration | G8: P&C SSO Integration (AuthZ) | H8: The IDE shall integrate the Planning and Collaboration capabilities with the Mandated Shared Service for Centralized Authorization (RBAC). | I8: Test | J8: Sec 2.1.2, 2.2 | K8: 4.3 ConOps | L8: Added
A9: 1 | B9: 1.1 | C9: 1.1.1-F8 | D9: Capability | E9: F | F9: Planning & Collaboration | G9: P&C Monitoring Integration | H9: The IDE shall integrate the Planning and Collaboration capabilities with the Mandated Shared Service for Centralized Monitoring. | I9: Test | J9: Sec 2.1.2, 2.2 | K9: 4.3 ConOps | L9: Added
A10: 1 | B10: 1.1 | C10: 1.1.2-F1 | D10: Capability | E10: F | F10: Systems Engineering | G10: SE Requirements Management Capability | H10: The IDE shall provide a capability for Requirements Management. | I10: Demonstrate | J10: Sec 2.2 | K10: 4.3 ConOps | L10: Updated
A11: 1 | B11: 1.1 | C11: 1.1.2-F2 | D11: Capability | E11: F | F11: Systems Engineering | G11: SE SSO Integration (AuthN) | H11: The IDE shall integrate the System Engineering capabilities with the Mandated Shared Service for Centralized Authentication (SSO). | I11: Test | J11: Sec 2.1.2, 2.2 | K11: 4.3 ConOps | L11: Updated
A12: 1 | B12: 1.1 | C12: 1.1.2-F3 | D12: Capability | E12: F | F12: Systems Engineering | G12: SE Logging Integration | H12: The IDE shall integrate the System Engineering capabilities with the Mandated Shared Service for Centralized Logging. | I12: Test | J12: Sec 2.1.2, 2.2 | K12: 4.3 ConOps | L12: Updated
A13: 1 | B13: 1.1 | C13: 1.1.2-F4 | D13: Capability | E13: F | F13: Systems Engineering | G13: SE Heavy Client Remote Access | H13: The IDE shall provide the 'Remote Application Access Service' for all System Engineering 'heavy client' applications. | I13: Demonstrate | J13: Sec 2.1.2, 2.2, 5.3.1 | K13: 4.3 ConOps | L13: Updated
... A37: 1 | B37: 1.1 | C37: 1.1.5-F4 | D37: Capability | E37: F | F37: Mechanical Engineering | G37: ME SSO Integration (AuthZ) | H37: The IDE shall integrate the Mechanical Engineering capability with the Mandated Shared Service for Centralized Authorization (RBAC). | I37: Test | J37: Sec 2.1.2, 2.2 | K37: 4.3 ConOps | L37: Added
A38: 1 | B38: 1.1 | C38: 1.1.6-M1 | D38: Capability | E38: F | F38: Product Quality | G38: User Feedback Collection | H38: The IDE shall provide a capability to collect, summarize, and review user feedback regarding product configurations and performance. | I38: Demonstrate | J38: Sec 2.2 | K38: Model | L38: Add - New from Modeled | M38: ConOps GAP
A39: 2 | B39: 2.1 | C39: 2.1.1-F1 | D39: Capability | E39: F | F39: Digital Thread | G39: Digital Thread Data Standardization | H39: The IDE shall provide a solution to standardize data element definitions from disparate Authoritative Sources of Truth (ASoTs) into a unified data model. | I39: Demonstrate | J39: Sec 2.2 | K39: 4.3 ConOps | L39: Updated
A40: 2 | B40: 2.1 | C40: 2.1.1-F2 | D40: AI | E40: F | F40: Digital Thread | G40: Digital Thread Graph ETL | H40: The IDE shall provide an automated ETL process to persist data element relationships from multiple disparate ASoTs into the 'GraphRAG (Graph) Database'. | I40: Test | J40: Sec 2.2, 2.3.1 | K40: 4.3 ConOps | L40: Updated
A41: 2 | B41: 2.1 | C41: 2.1.1-F3 | D41: AI | E41: F | F41: Digital Thread | G41: Digital Thread Relationship Query | H41: The IDE shall provide a capability (via the Insights Agent) to query the Digital Thread knowledge graph for complex, multi-domain relationships. | I41: Demonstrate | J41: Sec 2.3.1, 5.3.3 | K41: 4.3 ConOps | L41: Updated
A42: 2 | B42: 2.1 | C42: 2.1.2-F1 | D42: SP | E42: F | F42: Platform Monitoring & Admin | G42: Consolidated Pipeline (Platform Logs) | H42: The IDE shall provide a 'Centralized Logging and Monitoring' service as a consolidated pipeline for all platform logs. | I42: Test | J42: Sec 2.1.2, 3.3.3 | K42: 4.3 ConOps | L42: Updated
A43: 2 | B43: 2.1 | C43: 2.1.2-F2 | D43: SP | E43: F | F43: Platform Monitoring & Admin | G43: Health Dashboard (Health & KPI) | H43: The IDE shall provide a 'Centralized Health Dashboard' to display real-time health status, performance metrics, and Key Performance Indicators (KPIs) of all platform components. | I43: Demonstrate | J43: Sec 3.3.3 | K43: ConOps+Model | L43: Updated
A44: 2 | B44: 2.1 | C44: 2.1.2-F3 | D44: SP | E44: F | F44: Platform Monitoring & Admin | G44: Security Dashboard (Compliance) | H44: The IDE shall provide a 'Local Security Dashboard' to allow the Local Program Cyber Engineer to review compliance status. | I44: Demonstrate | J44: Sec 3.3.3, 4.2.1 | K44: 4.3 ConOps | L44: Updated
A45: 2 | B45: 2.1 | C45: 2.1.2-F4 | D45: SP | E45: F | F45: Platform Monitoring & Admin | G45: L3 Log Bundler (Collect Platform Logs) | H45: The IDE shall provide a 'Log Bundler Script' that collects platform logs required for L3 support escalation. | I45: Demonstrate | J45: Sec 3.3.3, 5.2.1 | K45: 4.3 ConOps | L45: Updated
A46: 2 | B46: 2.1 | C46: 2.1.2-F5 | D46: SP | E46: F | F46: Platform Monitoring & Admin | G46: Consolidated Admin Interface | H46: The IDE shall provide a 'Consolidated Admin Interface' as a secure, web-based UI to provide a single pane of glass for L1/L2 administrative tasks. | I46: Demonstrate | J46: Sec 3.3.3 | K46: 4.3 ConOps | L46: Updated
A47: 2 | B47: 2.1 | C47: 2.1.2-F6 | D47: SP | E47: F | F47: Platform Monitoring & Admin | G47: Admin Interface User Management | H47: The 'Consolidated Admin Interface' shall provide a module for managing user accounts. | I47: Demonstrate | J47: Sec 3.3.3 | K47: 4.3 ConOps | L47: Added
A48: 2 | B48: 2.1 | C48: 2.1.2-F7 | D48: SP | E48: F | F48: Platform Monitoring & Admin | G48: Admin Interface for Secrets | H48: The 'Consolidated Admin Interface' shall provide an administrative GUI for the 'Centralized Secrets Management' service. | I48: Demonstrate | J48: Sec 3.3.3 | K48: 4.3 ConOps | L48: Added
A49: 2 | B49: 2.1 | C49: 2.1.2-F8 | D49: SP | E49: F | F49: Platform Monitoring & Admin | G49: Consolidated Pipeline (App Logs) | H49: The IDE shall provide a 'Centralized Logging and Monitoring' service as a consolidated pipeline for all application logs. | I49: Test | J49: Sec 2.1.2, 3.3.3 | K49: 4.3 ConOps | L49: Added
A50: 2 | B50: 2.1 | C50: 2.1.2-F9 | D50: SP | E50: F | F50: Platform Monitoring & Admin | G50: Consolidated Pipeline (Health Metrics) | H50: The IDE shall provide a 'Centralized Logging and Monitoring' service as a consolidated pipeline for all health metrics. | I50: Test | J50: Sec 2.1.2, 3.3.3 | K50: 4.3 ConOps | L50: Added
... A60: 2 | B60: 2.1 | C60: 2.1.2-F19 | D60: SP | E60: F | F60: Platform Monitoring & Admin | G60: Admin Interface User Permissions | H60: The 'Consolidated Admin Interface' shall provide a module for managing platform-level access permissions. | I60: Demonstrate | J60: Sec 3.3.3 | K60: 4.3 ConOps | L60: Added
A61: 2 | B61: 2.1 | C61: 2.1.2-M1 | D61: SP | E61: F | F61: Data Reporting | G61: Configurable Dashboard Templates | H61: The IDE shall provide a capability for users to create and configure custom dashboard templates to accommodate various user needs and metrics. | I61: Demonstrate | J61: Sec 3.3.3 | K61: Model | L61: Add - New from Modeled | M61: ConOps GAP
A62: 2 | B62: 2.1 | C62: 2.1.2-M2 | D62: SP | E62: F | F62: Data Reporting | G62: Dashboard Documentation | H62: The IDE shall provide documentation and resources to assist users in configuring and interpreting dashboards. | I62: Inspection | J62: Sec 3.3.3 | K62: Model | L62: Add - New from Modeled | M62: ConOps GAP
A63: 2 | B63: 2.1 | C63: 2.1.2-M3 | D63: SP | E63: F | F63: Data Reporting | G63: Dashboard Interactive Analysis | H63: The IDE shall enable dashboard user interaction (e.g., drill-down, filtering) to perform detailed analysis. | I63: Demonstrate | J63: Sec 3.3.3 | K63: Model | L63: Add - New from Modeled | M63: ConOps GAP
A64: 2 | B64: 2.1 | C64: 2.1.3-F1 | D64: AI | E64: F | F64: AI Context | G64: RAG Data Ingestion | H64: The IDE shall provide a 'Vector Database' capability to ingest unstructured 'Customer Data' to provide context for AI Agents. | I64: Demonstrate | J64: Sec 2.3.1 | K64: 4.3 ConOps | L64: Updated
A65: 2 | B65: 2.1 | C65: 2.1.3-F2 | D65: AI | E65: F | F65: AI Context | G65: AI Session History Cache | H65: The IDE shall provide a 'Session Memory / History' cache for each user and agent to maintain conversational context during an interaction. | I65: Test | J65: Sec 2.3.1 | K65: ConOps | L65: None
A66: 2 | B66: 2.1 | C66: 2.1.3-F3 | D66: AI | E66: F | F66: AI Context | G66: RAG Data Indexing | H66: The IDE shall provide a 'Vector Database' capability to index ingested unstructured 'Customer Data' to provide context for AI Agents. | I66: Test | J66: Sec 2.3.1 | K66: 4.3 ConOps | L66: Added
A67: 2 | B67: 2.2 | C67: 2.2.1-F1 | D67: AI | E67: F | F67: AI Agents & Governance | G67: Generative AI Chatbot | H67: The IDE shall provide a 'Chatbot' capability to provide a general-purpose generative AI and Natural Language Processing (NLP) interface for end-users. | I67: Demonstrate | J67: Sec 2.3.1 | K67: ConOps | L67: None
A68: 2 | B68: 2.2 | C68: 2.2.1-F2 | D68: AI | E68: F | F68: AI Agents & Governance | G68: Agentic Loop (Plan) | H68: The IDE shall provide an 'Agentic Loop (Cognitive Engine)' that enables AI agents to decompose user goals into multi-step plans. | I68: Demonstrate | J68: Sec 2.3.1, 5.3.2 | K68: 4.3 ConOps | L68: Updated
A69: 2 | B69: 2.2 | C69: 2.2.1-F3 | D69: AI | E69: F | F69: AI Agents & Governance | G69: Developer Agent (Code Gen) | H69: The IDE shall provide a 'Developer Agent' persona integrated with the Software Factory (SWF) to assist with code generation. | I69: Demonstrate | J69: Sec 2.3.1, 5.3.2 | K69: 4.3 ConOps | L69: Updated
A70: 2 | B70: 2.2 | C70: 2.2.1-F4 | D70: AI | E70: F | F70: AI Agents & Governance | G70: Insights Agent Persona | H70: The IDE shall provide an 'Insights Agent' persona to perform complex, cross-domain queries of the Digital Thread (GraphRAG) and generate status reports. | I70: Demonstrate | J70: Sec 2.3.1, 5.3.3 | K70: ConOps | L70: None
A71: 2 | B71: 2.2 | C71: 2.2.1-F5 | D71: AI | E71: F | F71: AI Agents & Governance | G71: AIOps Agent (RCA) | H71: The IDE shall provide an 'IT Infrastructure Agent (AIOps)' persona integrated with the Centralized Logging service to perform autonomous root cause analysis. | I71: Demonstrate | J71: Sec 2.3.1, 5.3.4 | K71: 4.3 ConOps | L71: Updated
A72: 2 | B72: 2.2 | C72: 2.2.1-F6 | D72: AI | E72: F | F72: AI Agents & Governance | G72: AI Agent Tool Catalog | H72: The IDE shall provide a customer-configurable 'AI Tool Catalog' that defines the specific actions an AI agent is permitted to execute. | I72: Demonstrate | J72: Sec 2.3.1 | K72: 4.3 ConOps | L72: Updated
...
